try...catch 捕获错误
function greeting(){
  throw "Hello world";
}

function sayHi(){
  try{
    const data = greeting();
    console.log("It worked!", data);
  } catch(e){
    console.log("Oh na an error!", e);
  }
}

sayHi()
A: "It worked! Hello world!"
B: "Oh no an error: undefined
C: SyntaxError:can onlythrowErrorobjects
D: "Oh no an error: Hello world!
解：
1>通过 throw语句，我么可以创建自定义错误。
2>而通过它，我们可以抛出异常。
3>异常可以是一个字符串, 一个 数字, 一个 布尔类型 或者是一个 对象。在本例中，我们的异常是字符串 'Hello world'.
4>通过 catch语句，我们可以设定当 try语句块中抛出异常后应该做什么处理。
5>在本例中抛出的异常是字符串 'Hello world'. e就是这个字符串，因此被输出。最终结果就是 'Oh an error: Hello world'.
